<?xml version="1.0" ?>
<robot name="cleaning" xmlns:xacro="http://www.ros.org/wiki/xacro">

<xacro:include filename="$(find cleaning_description)/urdf/materials.xacro" />
<xacro:include filename="$(find cleaning_description)/urdf/cleaning.trans" />
<xacro:include filename="$(find cleaning_description)/urdf/cleaning.gazebo" />
<link name="base_link">
  <inertial>
    <origin xyz="0.058313304303346955 -0.015230594439995492 0.05613540854001533" rpy="0 0 0"/>
    <mass value="54.76161083841736"/>
    <inertia ixx="2.371896" iyy="1.181941" izz="3.1265" ixy="-0.0" iyz="-0.061127" ixz="-0.0"/>
  </inertial>
  <visual>
    <origin xyz="0 0 0" rpy="0 0 0"/>
    <geometry>
      <mesh filename="package://cleaning_description/meshes/base_link.stl" scale="0.001 0.001 0.001"/>
    </geometry>
    <material name="silver"/>
  </visual>
  <collision>
    <origin xyz="0 0 0" rpy="0 0 0"/>
    <geometry>
      <mesh filename="package://cleaning_description/meshes/base_link.stl" scale="0.001 0.001 0.001"/>
    </geometry>
  </collision>
</link>

<link name="left_motor_1">
  <inertial>
    <origin xyz="0.0016011540332543789 4.1376184034547236e-08 0.05000033555353705" rpy="0 0 0"/>
    <mass value="10.828701584350123"/>
    <inertia ixx="0.02872" iyy="0.017336" izz="0.028375" ixy="0.0" iyz="0.0" ixz="-0.0"/>
  </inertial>
  <visual>
    <origin xyz="-0.112725 -0.108724 0.009452" rpy="0 0 0"/>
    <geometry>
      <mesh filename="package://cleaning_description/meshes/left_motor_1.stl" scale="0.001 0.001 0.001"/>
    </geometry>
    <material name="silver"/>
  </visual>
  <collision>
    <origin xyz="-0.112725 -0.108724 0.009452" rpy="0 0 0"/>
    <geometry>
      <mesh filename="package://cleaning_description/meshes/left_motor_1.stl" scale="0.001 0.001 0.001"/>
    </geometry>
  </collision>
</link>

<link name="right_motor_1">
  <inertial>
    <origin xyz="-0.001601563486938557 4.1376184048425024e-08 0.05000033555353705" rpy="0 0 0"/>
    <mass value="10.82870158435012"/>
    <inertia ixx="0.02872" iyy="0.017336" izz="0.028375" ixy="0.0" iyz="0.0" ixz="0.0"/>
  </inertial>
  <visual>
    <origin xyz="-0.003902 -0.108724 0.009452" rpy="0 0 0"/>
    <geometry>
      <mesh filename="package://cleaning_description/meshes/right_motor_1.stl" scale="0.001 0.001 0.001"/>
    </geometry>
    <material name="silver"/>
  </visual>
  <collision>
    <origin xyz="-0.003902 -0.108724 0.009452" rpy="0 0 0"/>
    <geometry>
      <mesh filename="package://cleaning_description/meshes/right_motor_1.stl" scale="0.001 0.001 0.001"/>
    </geometry>
  </collision>
</link>

<link name="front_motor_1">
  <inertial>
    <origin xyz="2.9527315768135276e-07 3.3957881728774453e-07 0.03450033555353704" rpy="0 0 0"/>
    <mass value="18.760621360506445"/>
    <inertia ixx="0.059152" iyy="0.059152" izz="0.103418" ixy="0.0" iyz="0.0" ixz="0.0"/>
  </inertial>
  <visual>
    <origin xyz="-0.058313 0.111315 -0.021548" rpy="0 0 0"/>
    <geometry>
      <mesh filename="package://cleaning_description/meshes/front_motor_1.stl" scale="0.001 0.001 0.001"/>
    </geometry>
    <material name="silver"/>
  </visual>
  <collision>
    <origin xyz="-0.058313 0.111315 -0.021548" rpy="0 0 0"/>
    <geometry>
      <mesh filename="package://cleaning_description/meshes/front_motor_1.stl" scale="0.001 0.001 0.001"/>
    </geometry>
  </collision>
</link>

<link name="battery_base_1">
  <inertial>
    <origin xyz="0.09203709793147288 -1.2343095048827912e-07 -0.0003199233639099158" rpy="0 0 0"/>
    <mass value="2.9781372134875"/>
    <inertia ixx="0.012406" iyy="0.008632" izz="0.020995" ixy="0.0" iyz="0.0" ixz="0.0"/>
  </inertial>
  <visual>
    <origin xyz="0.033724 -0.103339 -0.095548" rpy="0 0 0"/>
    <geometry>
      <mesh filename="package://cleaning_description/meshes/battery_base_1.stl" scale="0.001 0.001 0.001"/>
    </geometry>
    <material name="silver"/>
  </visual>
  <collision>
    <origin xyz="0.033724 -0.103339 -0.095548" rpy="0 0 0"/>
    <geometry>
      <mesh filename="package://cleaning_description/meshes/battery_base_1.stl" scale="0.001 0.001 0.001"/>
    </geometry>
  </collision>
</link>

<link name="battery_1">
  <inertial>
    <origin xyz="2.9527315793115294e-07 -1.2343095047440134e-07 0.03500033555353704" rpy="0 0 0"/>
    <mass value="14.836499999999997"/>
    <inertia ixx="0.046117" iyy="0.033877" izz="0.067877" ixy="0.0" iyz="0.0" ixz="0.0"/>
  </inertial>
  <visual>
    <origin xyz="-0.058313 -0.103339 -0.099548" rpy="0 0 0"/>
    <geometry>
      <mesh filename="package://cleaning_description/meshes/battery_1.stl" scale="0.001 0.001 0.001"/>
    </geometry>
    <material name="silver"/>
  </visual>
  <collision>
    <origin xyz="-0.058313 -0.103339 -0.099548" rpy="0 0 0"/>
    <geometry>
      <mesh filename="package://cleaning_description/meshes/battery_1.stl" scale="0.001 0.001 0.001"/>
    </geometry>
  </collision>
</link>

<link name="charging_port_1">
  <inertial>
    <origin xyz="-0.00010178009298021651 -0.01617903306030516 3.3555353703973445e-07" rpy="0 0 0"/>
    <mass value="0.37493220914312686"/>
    <inertia ixx="9.5e-05" iyy="0.000129" izz="9.1e-05" ixy="0.0" iyz="0.0" ixz="0.0"/>
  </inertial>
  <visual>
    <origin xyz="-0.058313 -0.288441 -0.131548" rpy="0 0 0"/>
    <geometry>
      <mesh filename="package://cleaning_description/meshes/charging_port_1.stl" scale="0.001 0.001 0.001"/>
    </geometry>
    <material name="silver"/>
  </visual>
  <collision>
    <origin xyz="-0.058313 -0.288441 -0.131548" rpy="0 0 0"/>
    <geometry>
      <mesh filename="package://cleaning_description/meshes/charging_port_1.stl" scale="0.001 0.001 0.001"/>
    </geometry>
  </collision>
</link>

<link name="rear_wiper_motor_1">
  <inertial>
    <origin xyz="2.9527315812544197e-07 5.856211737764738e-09 0.009210861869326485" rpy="0 0 0"/>
    <mass value="0.11714213607072968"/>
    <inertia ixx="1.1e-05" iyy="1.1e-05" izz="1.3e-05" ixy="0.0" iyz="0.0" ixz="-0.0"/>
  </inertial>
  <visual>
    <origin xyz="-0.058313 -0.258441 0.008452" rpy="0 0 0"/>
    <geometry>
      <mesh filename="package://cleaning_description/meshes/rear_wiper_motor_1.stl" scale="0.001 0.001 0.001"/>
    </geometry>
    <material name="silver"/>
  </visual>
  <collision>
    <origin xyz="-0.058313 -0.258441 0.008452" rpy="0 0 0"/>
    <geometry>
      <mesh filename="package://cleaning_description/meshes/rear_wiper_motor_1.stl" scale="0.001 0.001 0.001"/>
    </geometry>
  </collision>
</link>

<link name="mixing_water_container_1">
  <inertial>
    <origin xyz="-0.030329665713304976 0.07150016237721724 0.08474270310992932" rpy="0 0 0"/>
    <mass value="6.685423159995114"/>
    <inertia ixx="0.076392" iyy="0.049979" izz="0.083597" ixy="-0.026993" iyz="-0.000597" ixz="-0.000128"/>
  </inertial>
  <visual>
    <origin xyz="-0.210406 0.244651 0.008452" rpy="0 0 0"/>
    <geometry>
      <mesh filename="package://cleaning_description/meshes/mixing_water_container_1.stl" scale="0.001 0.001 0.001"/>
    </geometry>
    <material name="silver"/>
  </visual>
  <collision>
    <origin xyz="-0.210406 0.244651 0.008452" rpy="0 0 0"/>
    <geometry>
      <mesh filename="package://cleaning_description/meshes/mixing_water_container_1.stl" scale="0.001 0.001 0.001"/>
    </geometry>
  </collision>
</link>

<link name="water_container_1">
  <inertial>
    <origin xyz="0.03589632073185816 0.0673580445124351 0.07953301958158605" rpy="0 0 0"/>
    <mass value="7.036433584291923"/>
    <inertia ixx="0.083947" iyy="0.058806" izz="0.091836" ixy="0.030871" iyz="-0.00413" ixz="0.004453"/>
  </inertial>
  <visual>
    <origin xyz="0.093779 0.244651 0.008452" rpy="0 0 0"/>
    <geometry>
      <mesh filename="package://cleaning_description/meshes/water_container_1.stl" scale="0.001 0.001 0.001"/>
    </geometry>
    <material name="silver"/>
  </visual>
  <collision>
    <origin xyz="0.093779 0.244651 0.008452" rpy="0 0 0"/>
    <geometry>
      <mesh filename="package://cleaning_description/meshes/water_container_1.stl" scale="0.001 0.001 0.001"/>
    </geometry>
  </collision>
</link>

<link name="liquid_mixing_motor_1">
  <inertial>
    <origin xyz="-2.871435284823587e-07 -0.015681776805634172 3.3555353703973445e-07" rpy="0 0 0"/>
    <mass value="0.6866687055198686"/>
    <inertia ixx="0.000211" iyy="0.0003" izz="0.000211" ixy="0.0" iyz="-0.0" ixz="0.0"/>
  </inertial>
  <visual>
    <origin xyz="-0.219326 0.035276 -0.094548" rpy="0 0 0"/>
    <geometry>
      <mesh filename="package://cleaning_description/meshes/liquid_mixing_motor_1.stl" scale="0.001 0.001 0.001"/>
    </geometry>
    <material name="silver"/>
  </visual>
  <collision>
    <origin xyz="-0.219326 0.035276 -0.094548" rpy="0 0 0"/>
    <geometry>
      <mesh filename="package://cleaning_description/meshes/liquid_mixing_motor_1.stl" scale="0.001 0.001 0.001"/>
    </geometry>
  </collision>
</link>

<link name="liquid_mixing_motor_blade_base_1">
  <inertial>
    <origin xyz="-2.8714362981796526e-07 0.0025000413761840506 3.355535370952456e-07" rpy="0 0 0"/>
    <mass value="0.07013114725287062"/>
    <inertia ixx="1.2e-05" iyy="2.4e-05" izz="1.2e-05" ixy="0.0" iyz="0.0" ixz="0.0"/>
  </inertial>
  <visual>
    <origin xyz="-0.219326 0.080276 -0.094548" rpy="0 0 0"/>
    <geometry>
      <mesh filename="package://cleaning_description/meshes/liquid_mixing_motor_blade_base_1.stl" scale="0.001 0.001 0.001"/>
    </geometry>
    <material name="silver"/>
  </visual>
  <collision>
    <origin xyz="-0.219326 0.080276 -0.094548" rpy="0 0 0"/>
    <geometry>
      <mesh filename="package://cleaning_description/meshes/liquid_mixing_motor_blade_base_1.stl" scale="0.001 0.001 0.001"/>
    </geometry>
  </collision>
</link>

<link name="liquid_mixing_motor_blade_1">
  <inertial>
    <origin xyz="-2.871436705353947e-07 -0.0020566895554743614 3.3555353702585666e-07" rpy="0 0 0"/>
    <mass value="0.04603639439574029"/>
    <inertia ixx="7e-06" iyy="1.4e-05" izz="7e-06" ixy="-0.0" iyz="0.0" ixz="-0.0"/>
  </inertial>
  <visual>
    <origin xyz="-0.219326 0.080276 -0.094548" rpy="0 0 0"/>
    <geometry>
      <mesh filename="package://cleaning_description/meshes/liquid_mixing_motor_blade_1.stl" scale="0.001 0.001 0.001"/>
    </geometry>
    <material name="silver"/>
  </visual>
  <collision>
    <origin xyz="-0.219326 0.080276 -0.094548" rpy="0 0 0"/>
    <geometry>
      <mesh filename="package://cleaning_description/meshes/liquid_mixing_motor_blade_1.stl" scale="0.001 0.001 0.001"/>
    </geometry>
  </collision>
</link>

<link name="mixing_water_container_lid_1">
  <inertial>
    <origin xyz="-0.02269201641014984 0.07240943616857537 0.002500335553537042" rpy="0 0 0"/>
    <mass value="1.0136541846429816"/>
    <inertia ixx="0.006439" iyy="0.00297" izz="0.009404" ixy="-0.003256" iyz="0.0" ixz="0.0"/>
  </inertial>
  <visual>
    <origin xyz="-0.210406 0.244651 -0.174548" rpy="0 0 0"/>
    <geometry>
      <mesh filename="package://cleaning_description/meshes/mixing_water_container_lid_1.stl" scale="0.001 0.001 0.001"/>
    </geometry>
    <material name="silver"/>
  </visual>
  <collision>
    <origin xyz="-0.210406 0.244651 -0.174548" rpy="0 0 0"/>
    <geometry>
      <mesh filename="package://cleaning_description/meshes/mixing_water_container_lid_1.stl" scale="0.001 0.001 0.001"/>
    </geometry>
  </collision>
</link>

<link name="water_container_lid_1">
  <inertial>
    <origin xyz="0.022691606956465063 0.07240943616857551 0.002500335553537042" rpy="0 0 0"/>
    <mass value="1.0136541846429814"/>
    <inertia ixx="0.006439" iyy="0.00297" izz="0.009404" ixy="0.003256" iyz="0.0" ixz="0.0"/>
  </inertial>
  <visual>
    <origin xyz="0.093779 0.244651 -0.174548" rpy="0 0 0"/>
    <geometry>
      <mesh filename="package://cleaning_description/meshes/water_container_lid_1.stl" scale="0.001 0.001 0.001"/>
    </geometry>
    <material name="silver"/>
  </visual>
  <collision>
    <origin xyz="0.093779 0.244651 -0.174548" rpy="0 0 0"/>
    <geometry>
      <mesh filename="package://cleaning_description/meshes/water_container_lid_1.stl" scale="0.001 0.001 0.001"/>
    </geometry>
  </collision>
</link>

<link name="top_front_botton_1">
  <inertial>
    <origin xyz="2.952731577646195e-07 5.0663418071916766e-08 0.004816630700308411" rpy="0 0 0"/>
    <mass value="0.05309934209418181"/>
    <inertia ixx="3e-06" iyy="3e-06" izz="6e-06" ixy="0.0" iyz="0.0" ixz="-0.0"/>
  </inertial>
  <visual>
    <origin xyz="-0.058313 -0.059676 -0.325548" rpy="0 0 0"/>
    <geometry>
      <mesh filename="package://cleaning_description/meshes/top_front_botton_1.stl" scale="0.001 0.001 0.001"/>
    </geometry>
    <material name="silver"/>
  </visual>
  <collision>
    <origin xyz="-0.058313 -0.059676 -0.325548" rpy="0 0 0"/>
    <geometry>
      <mesh filename="package://cleaning_description/meshes/top_front_botton_1.stl" scale="0.001 0.001 0.001"/>
    </geometry>
  </collision>
</link>

<link name="top_mid_buttom_1">
  <inertial>
    <origin xyz="2.9527315769523055e-07 1.8601420835595572e-07 0.004816630700308411" rpy="0 0 0"/>
    <mass value="0.0530993420941818"/>
    <inertia ixx="3e-06" iyy="3e-06" izz="6e-06" ixy="0.0" iyz="-0.0" ixz="0.0"/>
  </inertial>
  <visual>
    <origin xyz="-0.058313 -0.107711 -0.325548" rpy="0 0 0"/>
    <geometry>
      <mesh filename="package://cleaning_description/meshes/top_mid_buttom_1.stl" scale="0.001 0.001 0.001"/>
    </geometry>
    <material name="silver"/>
  </visual>
  <collision>
    <origin xyz="-0.058313 -0.107711 -0.325548" rpy="0 0 0"/>
    <geometry>
      <mesh filename="package://cleaning_description/meshes/top_mid_buttom_1.stl" scale="0.001 0.001 0.001"/>
    </geometry>
  </collision>
</link>

<link name="top_back_button_1">
  <inertial>
    <origin xyz="2.952731578895196e-07 -3.5879302540120506e-07 0.004816630700308411" rpy="0 0 0"/>
    <mass value="0.0530993420941818"/>
    <inertia ixx="3e-06" iyy="3e-06" izz="6e-06" ixy="0.0" iyz="0.0" ixz="0.0"/>
  </inertial>
  <visual>
    <origin xyz="-0.058313 -0.155718 -0.325548" rpy="0 0 0"/>
    <geometry>
      <mesh filename="package://cleaning_description/meshes/top_back_button_1.stl" scale="0.001 0.001 0.001"/>
    </geometry>
    <material name="silver"/>
  </visual>
  <collision>
    <origin xyz="-0.058313 -0.155718 -0.325548" rpy="0 0 0"/>
    <geometry>
      <mesh filename="package://cleaning_description/meshes/top_back_button_1.stl" scale="0.001 0.001 0.001"/>
    </geometry>
  </collision>
</link>

<link name="top_body_1">
  <inertial>
    <origin xyz="2.956470174161896e-07 0.04222472026673674 0.04714612335749818" rpy="0 0 0"/>
    <mass value="161.3221769861006"/>
    <inertia ixx="3.821764" iyy="2.215417" izz="5.696169" ixy="1e-06" iyz="-0.175246" ixz="0.0"/>
  </inertial>
  <visual>
    <origin xyz="-0.058313 0.016359 -0.181548" rpy="0 0 0"/>
    <geometry>
      <mesh filename="package://cleaning_description/meshes/top_body_1.stl" scale="0.001 0.001 0.001"/>
    </geometry>
    <material name="silver"/>
  </visual>
  <collision>
    <origin xyz="-0.058313 0.016359 -0.181548" rpy="0 0 0"/>
    <geometry>
      <mesh filename="package://cleaning_description/meshes/top_body_1.stl" scale="0.001 0.001 0.001"/>
    </geometry>
  </collision>
</link>

<link name="water_container_cap_1">
  <inertial>
    <origin xyz="-0.016396655246805253 -4.763838157423317e-07 -1.6444646300239896e-07" rpy="0 0 0"/>
    <mass value="0.3427901670674076"/>
    <inertia ixx="8.3e-05" iyy="6.8e-05" izz="6.8e-05" ixy="0.0" iyz="0.0" ixz="-0.0"/>
  </inertial>
  <visual>
    <origin xyz="0.150287 0.063717 -0.142107" rpy="0 0 0"/>
    <geometry>
      <mesh filename="package://cleaning_description/meshes/water_container_cap_1.stl" scale="0.001 0.001 0.001"/>
    </geometry>
    <material name="silver"/>
  </visual>
  <collision>
    <origin xyz="0.150287 0.063717 -0.142107" rpy="0 0 0"/>
    <geometry>
      <mesh filename="package://cleaning_description/meshes/water_container_cap_1.stl" scale="0.001 0.001 0.001"/>
    </geometry>
  </collision>
</link>

<link name="mixing_water_container_cap_1">
  <inertial>
    <origin xyz="0.01639724579312063 -4.7638381589498735e-07 -1.6444646300239896e-07" rpy="0 0 0"/>
    <mass value="0.34279016706740756"/>
    <inertia ixx="8.3e-05" iyy="6.8e-05" izz="6.8e-05" ixy="0.0" iyz="0.0" ixz="0.0"/>
  </inertial>
  <visual>
    <origin xyz="-0.266913 0.063717 -0.142107" rpy="0 0 0"/>
    <geometry>
      <mesh filename="package://cleaning_description/meshes/mixing_water_container_cap_1.stl" scale="0.001 0.001 0.001"/>
    </geometry>
    <material name="silver"/>
  </visual>
  <collision>
    <origin xyz="-0.266913 0.063717 -0.142107" rpy="0 0 0"/>
    <geometry>
      <mesh filename="package://cleaning_description/meshes/mixing_water_container_cap_1.stl" scale="0.001 0.001 0.001"/>
    </geometry>
  </collision>
</link>

<link name="right_wheel_1">
  <inertial>
    <origin xyz="0.011832266255614829 -4.533670386663857e-06 -1.5005397828837808e-05" rpy="0 0 0"/>
    <mass value="5.016213936854125"/>
    <inertia ixx="0.020891" iyy="0.011227" izz="0.011229" ixy="0.0" iyz="1e-06" ixz="-0.0"/>
  </inertial>
  <visual>
    <origin xyz="0.101098 -0.108724 -0.040548" rpy="0 0 0"/>
    <geometry>
      <mesh filename="package://cleaning_description/meshes/right_wheel_1.stl" scale="0.001 0.001 0.001"/>
    </geometry>
    <material name="silver"/>
  </visual>
  <collision>
    <origin xyz="0.101098 -0.108724 -0.040548" rpy="0 0 0"/>
    <geometry>
      <mesh filename="package://cleaning_description/meshes/right_wheel_1.stl" scale="0.001 0.001 0.001"/>
    </geometry>
  </collision>
</link>

<link name="left_wheel_1">
  <inertial>
    <origin xyz="-0.0118326266092951 -4.3958964564966285e-06 -1.4905830706728185e-05" rpy="0 0 0"/>
    <mass value="5.0162154535608305"/>
    <inertia ixx="0.020891" iyy="0.011227" izz="0.011229" ixy="-0.0" iyz="1e-06" ixz="0.0"/>
  </inertial>
  <visual>
    <origin xyz="-0.217725 -0.108724 -0.040548" rpy="0 0 0"/>
    <geometry>
      <mesh filename="package://cleaning_description/meshes/left_wheel_1.stl" scale="0.001 0.001 0.001"/>
    </geometry>
    <material name="silver"/>
  </visual>
  <collision>
    <origin xyz="-0.217725 -0.108724 -0.040548" rpy="0 0 0"/>
    <geometry>
      <mesh filename="package://cleaning_description/meshes/left_wheel_1.stl" scale="0.001 0.001 0.001"/>
    </geometry>
  </collision>
</link>

<link name="right_tyre_1">
  <inertial>
    <origin xyz="-3.889571081189258e-07 4.1376184117813963e-08 3.355535370813678e-07" rpy="0 0 0"/>
    <mass value="13.208345588113446"/>
    <inertia ixx="0.140179" iyy="0.076538" izz="0.076538" ixy="0.0" iyz="0.0" ixz="-0.0"/>
  </inertial>
  <visual>
    <origin xyz="0.089224 -0.108724 -0.040548" rpy="0 0 0"/>
    <geometry>
      <mesh filename="package://cleaning_description/meshes/right_tyre_1.stl" scale="0.001 0.001 0.001"/>
    </geometry>
    <material name="silver"/>
  </visual>
  <collision>
    <origin xyz="0.089224 -0.108724 -0.040548" rpy="0 0 0"/>
    <geometry>
      <mesh filename="package://cleaning_description/meshes/right_tyre_1.stl" scale="0.001 0.001 0.001"/>
    </geometry>
  </collision>
</link>

<link name="left_tyre_1">
  <inertial>
    <origin xyz="-2.0496575992012822e-08 4.1376184034547236e-08 3.355535370883067e-07" rpy="0 0 0"/>
    <mass value="13.208345588113465"/>
    <inertia ixx="0.140179" iyy="0.076538" izz="0.076538" ixy="0.0" iyz="0.0" ixz="0.0"/>
  </inertial>
  <visual>
    <origin xyz="-0.205851 -0.108724 -0.040548" rpy="0 0 0"/>
    <geometry>
      <mesh filename="package://cleaning_description/meshes/left_tyre_1.stl" scale="0.001 0.001 0.001"/>
    </geometry>
    <material name="silver"/>
  </visual>
  <collision>
    <origin xyz="-0.205851 -0.108724 -0.040548" rpy="0 0 0"/>
    <geometry>
      <mesh filename="package://cleaning_description/meshes/left_tyre_1.stl" scale="0.001 0.001 0.001"/>
    </geometry>
  </collision>
</link>

<link name="rear_wiper_base_1">
  <inertial>
    <origin xyz="2.952731581115642e-07 5.8561808180535024e-09 -0.004999664446462944" rpy="0 0 0"/>
    <mass value="0.9358346244173298"/>
    <inertia ixx="7.8e-05" iyy="0.012568" izz="0.012631" ixy="0.0" iyz="0.0" ixz="0.0"/>
  </inertial>
  <visual>
    <origin xyz="-0.058313 -0.258441 0.018452" rpy="0 0 0"/>
    <geometry>
      <mesh filename="package://cleaning_description/meshes/rear_wiper_base_1.stl" scale="0.001 0.001 0.001"/>
    </geometry>
    <material name="silver"/>
  </visual>
  <collision>
    <origin xyz="-0.058313 -0.258441 0.018452" rpy="0 0 0"/>
    <geometry>
      <mesh filename="package://cleaning_description/meshes/rear_wiper_base_1.stl" scale="0.001 0.001 0.001"/>
    </geometry>
  </collision>
</link>

<link name="rear_wiper_foam_1">
  <inertial>
    <origin xyz="2.9527315805605303e-07 5.856184870367542e-09 -0.023407045900391322" rpy="0 0 0"/>
    <mass value="4.4003504100972295"/>
    <inertia ixx="0.001135" iyy="0.059092" izz="0.058576" ixy="0.0" iyz="-0.0" ixz="-0.0"/>
  </inertial>
  <visual>
    <origin xyz="-0.058313 -0.258441 0.028452" rpy="0 0 0"/>
    <geometry>
      <mesh filename="package://cleaning_description/meshes/rear_wiper_foam_1.stl" scale="0.001 0.001 0.001"/>
    </geometry>
    <material name="silver"/>
  </visual>
  <collision>
    <origin xyz="-0.058313 -0.258441 0.028452" rpy="0 0 0"/>
    <geometry>
      <mesh filename="package://cleaning_description/meshes/rear_wiper_foam_1.stl" scale="0.001 0.001 0.001"/>
    </geometry>
  </collision>
</link>

<link name="front_top_sensor_1">
  <inertial>
    <origin xyz="2.952731574176748e-07 -0.004674554138165032 3.3555353705361224e-07" rpy="0 0 0"/>
    <mass value="0.03552138340949737"/>
    <inertia ixx="2e-06" iyy="3e-06" izz="2e-06" ixy="0.0" iyz="-0.0" ixz="0.0"/>
  </inertial>
  <visual>
    <origin xyz="-0.058313 0.316159 -0.111548" rpy="0 0 0"/>
    <geometry>
      <mesh filename="package://cleaning_description/meshes/front_top_sensor_1.stl" scale="0.001 0.001 0.001"/>
    </geometry>
    <material name="silver"/>
  </visual>
  <collision>
    <origin xyz="-0.058313 0.316159 -0.111548" rpy="0 0 0"/>
    <geometry>
      <mesh filename="package://cleaning_description/meshes/front_top_sensor_1.stl" scale="0.001 0.001 0.001"/>
    </geometry>
  </collision>
</link>

<link name="front_bottom_sensor_1">
  <inertial>
    <origin xyz="2.952731574176748e-07 -0.004674554138165032 3.3555353703279556e-07" rpy="0 0 0"/>
    <mass value="0.0355213834094974"/>
    <inertia ixx="2e-06" iyy="3e-06" izz="2e-06" ixy="0.0" iyz="0.0" ixz="0.0"/>
  </inertial>
  <visual>
    <origin xyz="-0.058313 0.316159 -0.061548" rpy="0 0 0"/>
    <geometry>
      <mesh filename="package://cleaning_description/meshes/front_bottom_sensor_1.stl" scale="0.001 0.001 0.001"/>
    </geometry>
    <material name="silver"/>
  </visual>
  <collision>
    <origin xyz="-0.058313 0.316159 -0.061548" rpy="0 0 0"/>
    <geometry>
      <mesh filename="package://cleaning_description/meshes/front_bottom_sensor_1.stl" scale="0.001 0.001 0.001"/>
    </geometry>
  </collision>
</link>

<link name="front_motor_gear_1">
  <inertial>
    <origin xyz="2.9527315767441387e-07 3.3957881728774453e-07 -0.014999664446462951" rpy="0 0 0"/>
    <mass value="0.3468023765251856"/>
    <inertia ixx="9.4e-05" iyy="9.4e-05" izz="0.000135" ixy="0.0" iyz="0.0" ixz="0.0"/>
  </inertial>
  <visual>
    <origin xyz="-0.058313 0.111315 -0.021548" rpy="0 0 0"/>
    <geometry>
      <mesh filename="package://cleaning_description/meshes/front_motor_gear_1.stl" scale="0.001 0.001 0.001"/>
    </geometry>
    <material name="silver"/>
  </visual>
  <collision>
    <origin xyz="-0.058313 0.111315 -0.021548" rpy="0 0 0"/>
    <geometry>
      <mesh filename="package://cleaning_description/meshes/front_motor_gear_1.stl" scale="0.001 0.001 0.001"/>
    </geometry>
  </collision>
</link>

<link name="front_motor_axcel_1">
  <inertial>
    <origin xyz="2.9527315767441387e-07 3.3957881727386674e-07 -0.019999664446462943" rpy="0 0 0"/>
    <mass value="0.15413438956674919"/>
    <inertia ixx="2.7e-05" iyy="2.7e-05" izz="1.2e-05" ixy="0.0" iyz="-0.0" ixz="-0.0"/>
  </inertial>
  <visual>
    <origin xyz="-0.058313 0.111315 -0.021548" rpy="0 0 0"/>
    <geometry>
      <mesh filename="package://cleaning_description/meshes/front_motor_axcel_1.stl" scale="0.001 0.001 0.001"/>
    </geometry>
    <material name="silver"/>
  </visual>
  <collision>
    <origin xyz="-0.058313 0.111315 -0.021548" rpy="0 0 0"/>
    <geometry>
      <mesh filename="package://cleaning_description/meshes/front_motor_axcel_1.stl" scale="0.001 0.001 0.001"/>
    </geometry>
  </collision>
</link>

<link name="front_cleaning_blade_1">
  <inertial>
    <origin xyz="2.9527315769523055e-07 3.3957878586843293e-07 -0.007547785028479484" rpy="0 0 0"/>
    <mass value="4.003858201304152"/>
    <inertia ixx="0.010524" iyy="0.010524" izz="0.020633" ixy="0.0" iyz="0.0" ixz="0.0"/>
  </inertial>
  <visual>
    <origin xyz="-0.058313 0.111315 0.018452" rpy="0 0 0"/>
    <geometry>
      <mesh filename="package://cleaning_description/meshes/front_cleaning_blade_1.stl" scale="0.001 0.001 0.001"/>
    </geometry>
    <material name="silver"/>
  </visual>
  <collision>
    <origin xyz="-0.058313 0.111315 0.018452" rpy="0 0 0"/>
    <geometry>
      <mesh filename="package://cleaning_description/meshes/front_cleaning_blade_1.stl" scale="0.001 0.001 0.001"/>
    </geometry>
  </collision>
</link>

<link name="front_cleaning_foam_1">
  <inertial>
    <origin xyz="2.952731576605361e-07 3.3957881728774453e-07 -0.01907767606518388" rpy="0 0 0"/>
    <mass value="6.098442604880595"/>
    <inertia ixx="0.016082" iyy="0.016082" izz="0.030651" ixy="0.0" iyz="-0.0" ixz="0.0"/>
  </inertial>
  <visual>
    <origin xyz="-0.058313 0.111315 0.038452" rpy="0 0 0"/>
    <geometry>
      <mesh filename="package://cleaning_description/meshes/front_cleaning_foam_1.stl" scale="0.001 0.001 0.001"/>
    </geometry>
    <material name="silver"/>
  </visual>
  <collision>
    <origin xyz="-0.058313 0.111315 0.038452" rpy="0 0 0"/>
    <geometry>
      <mesh filename="package://cleaning_description/meshes/front_cleaning_foam_1.stl" scale="0.001 0.001 0.001"/>
    </geometry>
  </collision>
</link>

<link name="front_caster_wheel_1">
  <inertial>
    <origin xyz="2.952731574384915e-07 -2.369129574186779e-07 3.355535370744289e-07" rpy="0 0 0"/>
    <mass value="0.049323004661359714"/>
    <inertia ixx="5e-06" iyy="4e-06" izz="4e-06" ixy="0.0" iyz="-0.0" ixz="-0.0"/>
  </inertial>
  <visual>
    <origin xyz="-0.058313 0.27104 0.05445" rpy="0 0 0"/>
    <geometry>
      <mesh filename="package://cleaning_description/meshes/front_caster_wheel_1.stl" scale="0.001 0.001 0.001"/>
    </geometry>
    <material name="silver"/>
  </visual>
  <collision>
    <origin xyz="-0.058313 0.27104 0.05445" rpy="0 0 0"/>
    <geometry>
      <mesh filename="package://cleaning_description/meshes/front_caster_wheel_1.stl" scale="0.001 0.001 0.001"/>
    </geometry>
  </collision>
</link>

<link name="front_caster_tyre_1">
  <inertial>
    <origin xyz="2.952731574384915e-07 -2.369129575297002e-07 3.3555353706055113e-07" rpy="0 0 0"/>
    <mass value="0.21856165176881648"/>
    <inertia ixx="8.3e-05" iyy="4.8e-05" izz="4.8e-05" ixy="0.0" iyz="0.0" ixz="0.0"/>
  </inertial>
  <visual>
    <origin xyz="-0.058313 0.27104 0.05445" rpy="0 0 0"/>
    <geometry>
      <mesh filename="package://cleaning_description/meshes/front_caster_tyre_1.stl" scale="0.001 0.001 0.001"/>
    </geometry>
    <material name="silver"/>
  </visual>
  <collision>
    <origin xyz="-0.058313 0.27104 0.05445" rpy="0 0 0"/>
    <geometry>
      <mesh filename="package://cleaning_description/meshes/front_caster_tyre_1.stl" scale="0.001 0.001 0.001"/>
    </geometry>
  </collision>
</link>

<link name="lidar_base_1">
  <inertial>
    <origin xyz="-0.058313704725144265 0.01635900578301637 0.04695133555353703" rpy="0 0 0"/>
    <mass value="3.514670794783126"/>
    <inertia ixx="0.003148" iyy="0.003149" izz="0.004394" ixy="0.0" iyz="0.0" ixz="0.0"/>
  </inertial>
  <visual>
    <origin xyz="-0.116627 0.082718 -0.262097" rpy="0 0 0"/>
    <geometry>
      <mesh filename="package://cleaning_description/meshes/lidar_base_1.stl" scale="0.001 0.001 0.001"/>
    </geometry>
    <material name="silver"/>
  </visual>
  <collision>
    <origin xyz="-0.116627 0.082718 -0.262097" rpy="0 0 0"/>
    <geometry>
      <mesh filename="package://cleaning_description/meshes/lidar_base_1.stl" scale="0.001 0.001 0.001"/>
    </geometry>
  </collision>
</link>

<link name="lidar_1">
  <inertial>
    <origin xyz="2.952731529698438e-07 5.814961581696032e-09 0.020178888448717347" rpy="0 0 0"/>
    <mass value="2.4583298036611483"/>
    <inertia ixx="0.0018" iyy="0.0018" izz="0.002906" ixy="0.0" iyz="-0.0" ixz="-0.0"/>
  </inertial>
  <visual>
    <origin xyz="-0.058313 0.066359 -0.337548" rpy="0 0 0"/>
    <geometry>
      <mesh filename="package://cleaning_description/meshes/lidar_1.stl" scale="0.001 0.001 0.001"/>
    </geometry>
    <material name="silver"/>
  </visual>
  <collision>
    <origin xyz="-0.058313 0.066359 -0.337548" rpy="0 0 0"/>
    <geometry>
      <mesh filename="package://cleaning_description/meshes/lidar_1.stl" scale="0.001 0.001 0.001"/>
    </geometry>
  </collision>
</link>

<joint name="left_motor_joint" type="fixed">
  <origin xyz="0.112725 0.108724 -0.009452" rpy="0 0 0"/>
  <parent link="base_link"/>
  <child link="left_motor_1"/>
</joint>

<joint name="right_motor_joint" type="fixed">
  <origin xyz="0.003902 0.108724 -0.009452" rpy="0 0 0"/>
  <parent link="base_link"/>
  <child link="right_motor_1"/>
</joint>

<joint name="front_motor_joint" type="fixed">
  <origin xyz="0.058313 -0.111315 0.021548" rpy="0 0 0"/>
  <parent link="base_link"/>
  <child link="front_motor_1"/>
</joint>

<joint name="battery_base_joint" type="fixed">
  <origin xyz="-0.033724 0.103339 0.095548" rpy="0 0 0"/>
  <parent link="base_link"/>
  <child link="battery_base_1"/>
</joint>

<joint name="battery_joint" type="fixed">
  <origin xyz="0.092037 0.0 0.004" rpy="0 0 0"/>
  <parent link="battery_base_1"/>
  <child link="battery_1"/>
</joint>

<joint name="charging_port_joint" type="fixed">
  <origin xyz="0.058313 0.288441 0.131548" rpy="0 0 0"/>
  <parent link="base_link"/>
  <child link="charging_port_1"/>
</joint>

<joint name="back_wiper_motor" type="fixed">
  <origin xyz="0.058313 0.258441 -0.008452" rpy="0 0 0"/>
  <parent link="base_link"/>
  <child link="rear_wiper_motor_1"/>
</joint>

<joint name="mixing_water_container_joint" type="fixed">
  <origin xyz="0.210406 -0.244651 -0.008452" rpy="0 0 0"/>
  <parent link="base_link"/>
  <child link="mixing_water_container_1"/>
</joint>

<joint name="water_container_joint" type="fixed">
  <origin xyz="-0.093779 -0.244651 -0.008452" rpy="0 0 0"/>
  <parent link="base_link"/>
  <child link="water_container_1"/>
</joint>

<joint name="liquid_mixing_motor_joint" type="fixed">
  <origin xyz="0.00892 0.209375 0.103" rpy="0 0 0"/>
  <parent link="mixing_water_container_1"/>
  <child link="liquid_mixing_motor_1"/>
</joint>

<joint name="liquid_mixing_motor_blade_base_joint" type="continuous">
  <origin xyz="0.0 -0.045 0.0" rpy="0 0 0"/>
  <parent link="liquid_mixing_motor_1"/>
  <child link="liquid_mixing_motor_blade_base_1"/>
  <axis xyz="-0.0 -1.0 -0.0"/>
</joint>

<joint name="liquid_mixing_motor_blade" type="fixed">
  <origin xyz="0.0 0.0 0.0" rpy="0 0 0"/>
  <parent link="liquid_mixing_motor_blade_base_1"/>
  <child link="liquid_mixing_motor_blade_1"/>
</joint>

<joint name="mixing_water_container_lid_joint" type="fixed">
  <origin xyz="0.0 0.0 0.183" rpy="0 0 0"/>
  <parent link="mixing_water_container_1"/>
  <child link="mixing_water_container_lid_1"/>
</joint>

<joint name="water_container_lid_joint" type="fixed">
  <origin xyz="0.0 0.0 0.183" rpy="0 0 0"/>
  <parent link="water_container_1"/>
  <child link="water_container_lid_1"/>
</joint>

<joint name="top_front_button_joint" type="fixed">
  <origin xyz="0.0 0.076035 0.144" rpy="0 0 0"/>
  <parent link="top_body_1"/>
  <child link="top_front_botton_1"/>
</joint>

<joint name="top_mid_button_joint" type="fixed">
  <origin xyz="0.0 0.12407 0.144" rpy="0 0 0"/>
  <parent link="top_body_1"/>
  <child link="top_mid_buttom_1"/>
</joint>

<joint name="top_back_button_joint" type="fixed">
  <origin xyz="0.0 0.172077 0.144" rpy="0 0 0"/>
  <parent link="top_body_1"/>
  <child link="top_back_button_1"/>
</joint>

<joint name="top_base_joint" type="fixed">
  <origin xyz="0.058313 -0.016359 0.181548" rpy="0 0 0"/>
  <parent link="base_link"/>
  <child link="top_body_1"/>
</joint>

<joint name="water_container_cap_joint" type="fixed">
  <origin xyz="-0.056508 0.180934 0.150559" rpy="0 0 0"/>
  <parent link="water_container_1"/>
  <child link="water_container_cap_1"/>
</joint>

<joint name="mixing_water_container_cap_joint" type="fixed">
  <origin xyz="0.056507 0.180934 0.150559" rpy="0 0 0"/>
  <parent link="mixing_water_container_1"/>
  <child link="mixing_water_container_cap_1"/>
</joint>

<joint name="right_wheel_joint" type="continuous">
  <origin xyz="-0.105 0.0 0.05" rpy="0 0 0"/>
  <parent link="right_motor_1"/>
  <child link="right_wheel_1"/>
  <axis xyz="-1.0 0.0 0.0"/>
</joint>

<joint name="left_wheel_joint" type="continuous">
  <origin xyz="0.105 0.0 0.05" rpy="0 0 0"/>
  <parent link="left_motor_1"/>
  <child link="left_wheel_1"/>
  <axis xyz="1.0 -0.0 -0.0"/>
</joint>

<joint name="right_tyre_joint" type="fixed">
  <origin xyz="0.011874 0.0 0.0" rpy="0 0 0"/>
  <parent link="right_wheel_1"/>
  <child link="right_tyre_1"/>
</joint>

<joint name="left_tyre_joint" type="fixed">
  <origin xyz="-0.011874 0.0 0.0" rpy="0 0 0"/>
  <parent link="left_wheel_1"/>
  <child link="left_tyre_1"/>
</joint>

<joint name="rear_wiper_base_joint" type="revolute">
  <origin xyz="0.0 0.0 -0.01" rpy="0 0 0"/>
  <parent link="rear_wiper_motor_1"/>
  <child link="rear_wiper_base_1"/>
  <axis xyz="0.0 -0.0 1.0"/>
  <limit upper="0.087266" lower="-0.087266" effort="100" velocity="100"/>
</joint>

<joint name="rear_wiper_foam_joint" type="fixed">
  <origin xyz="0.0 0.0 -0.01" rpy="0 0 0"/>
  <parent link="rear_wiper_base_1"/>
  <child link="rear_wiper_foam_1"/>
</joint>

<joint name="front_top_sensor_joint" type="fixed">
  <origin xyz="0.058313 -0.316159 0.111548" rpy="0 0 0"/>
  <parent link="base_link"/>
  <child link="front_top_sensor_1"/>
</joint>

<joint name="front_button_sensor_joint" type="fixed">
  <origin xyz="0.058313 -0.316159 0.061548" rpy="0 0 0"/>
  <parent link="base_link"/>
  <child link="front_bottom_sensor_1"/>
</joint>

<joint name="front_motor_gear_joint" type="fixed">
  <origin xyz="0.0 0.0 0.0" rpy="0 0 0"/>
  <parent link="front_motor_1"/>
  <child link="front_motor_gear_1"/>
</joint>

<joint name="front_cleaning_blade_joint" type="continuous">
  <origin xyz="0.0 0.0 0.0" rpy="0 0 0"/>
  <parent link="front_motor_gear_1"/>
  <child link="front_motor_axcel_1"/>
  <axis xyz="0.0 -0.0 1.0"/>
</joint>

<joint name="front_cleaning_base_joint" type="fixed">
  <origin xyz="0.0 0.0 -0.04" rpy="0 0 0"/>
  <parent link="front_motor_axcel_1"/>
  <child link="front_cleaning_blade_1"/>
</joint>

<joint name="front_cleaning_foam_joint" type="fixed">
  <origin xyz="0.0 0.0 -0.02" rpy="0 0 0"/>
  <parent link="front_cleaning_blade_1"/>
  <child link="front_cleaning_foam_1"/>
</joint>

<joint name="front_caster_wheel_joint" type="continuous">
  <origin xyz="0.152092 -0.026389 -0.045998" rpy="0 0 0"/>
  <parent link="water_container_1"/>
  <child link="front_caster_wheel_1"/>
  <axis xyz="1.0 -0.0 -0.0"/>
</joint>

<joint name="front_caster_tyre_joint" type="fixed">
  <origin xyz="0.0 0.0 0.0" rpy="0 0 0"/>
  <parent link="front_caster_wheel_1"/>
  <child link="front_caster_tyre_1"/>
</joint>

<joint name="Rigid 36" type="fixed">
  <origin xyz="0.058314 -0.066359 0.080549" rpy="0 0 0"/>
  <parent link="top_body_1"/>
  <child link="lidar_base_1"/>
</joint>

<joint name="Rigid 37" type="fixed">
  <origin xyz="-0.058314 0.016359 0.075451" rpy="0 0 0"/>
  <parent link="lidar_base_1"/>
  <child link="lidar_1"/>
</joint>

</robot>
